Map (num_proc=3):   0%|          | 0/22 [00:00<?, ? examples/s]Map (num_proc=3):  32%|███▏      | 7/22 [00:02<00:05,  2.64 examples/s]Map (num_proc=3):  64%|██████▎   | 14/22 [00:04<00:02,  3.28 examples/s]Map (num_proc=3): 100%|██████████| 22/22 [00:04<00:00,  6.13 examples/s]Traceback (most recent call last):
  File "/home/share/huadjyin/home/baiyong01/.conda/envs/py10/lib/python3.10/site-packages/multiprocess/process.py", line 314, in _bootstrap
    self.run()
  File "/home/share/huadjyin/home/baiyong01/.conda/envs/py10/lib/python3.10/site-packages/multiprocess/process.py", line 108, in run
    self._target(*self._args, **self._kwargs)
  File "/home/share/huadjyin/home/baiyong01/.conda/envs/py10/lib/python3.10/site-packages/multiprocess/managers.py", line 599, in _run_server
    server.serve_forever()
  File "/home/share/huadjyin/home/baiyong01/.conda/envs/py10/lib/python3.10/site-packages/multiprocess/managers.py", line 184, in serve_forever
    sys.exit(0)
SystemExit: 0

During handling of the above exception, another exception occurred:

Traceback (most recent call last):
  File "/home/share/huadjyin/home/baiyong01/.conda/envs/py10/lib/python3.10/site-packages/multiprocess/util.py", line 300, in _run_finalizers
    finalizer()
  File "/home/share/huadjyin/home/baiyong01/.conda/envs/py10/lib/python3.10/site-packages/multiprocess/util.py", line 224, in __call__
    res = self._callback(*self._args, **self._kwargs)
  File "/home/share/huadjyin/home/baiyong01/.conda/envs/py10/lib/python3.10/site-packages/multiprocess/util.py", line 133, in _remove_temp_dir
    rmtree(tempdir)
  File "/home/share/huadjyin/home/baiyong01/.conda/envs/py10/lib/python3.10/shutil.py", line 725, in rmtree
    _rmtree_safe_fd(fd, path, onerror)
  File "/home/share/huadjyin/home/baiyong01/.conda/envs/py10/lib/python3.10/shutil.py", line 681, in _rmtree_safe_fd
    onerror(os.unlink, fullname, sys.exc_info())
  File "/home/share/huadjyin/home/baiyong01/.conda/envs/py10/lib/python3.10/shutil.py", line 679, in _rmtree_safe_fd
    os.unlink(entry.name, dir_fd=topfd)
OSError: [Errno 16] Device or resource busy: '.__dpc000000007f6b48cc00007b76'
Map (num_proc=3): 100%|██████████| 22/22 [00:04<00:00,  4.56 examples/s]
